Workbook

Sheet Cover

Sheet Assumptions
E1: Operating Drivers / Assumptions
A3: Driver | C3: FY23 | D3: FY24 | E3: FY25 | F3: FY26 | G3: FY27 | H3: FY28 | I3: FY29 | J3: FY30
A4: Revenue Growth % | C4: 0 | D4: =(IS!D5/IS!C5)-1 -> 0.23913429 | E4: =(IS!E5/IS!D5)-1 -> 0.060649444 | F4: 0.07 | G4: 0.07 | H4: 0.068 | I4: 0.065 | J4: 0.065
A6: Margins
A7: EBIT Margit | C7: =IS!C29/IS!C5 -> 0.25642266 | D7: =IS!D29/IS!D5 -> 0.23724865 | E7: =IS!E29/IS!E5 -> 0.23329039 | F7: 0.233 | G7: 0.234 | H7: 0.235 | I7: 0.235 | J7: 0.235
A8: Net Margin | C8: =IS!C27/IS!C5 -> 0.18762398 | D8: =IS!D27/IS!D5 -> 0.17080757 | E8: =IS!E27/IS!E5 -> 0.1641205 | F8: 0.165 | G8: 0.165 | H8: 0.166 | I8: 0.166 | J8: 0.167
A10: Working capital
A11: DSO | C11: =BS!C25/IS!C5*365 -> 61.139428 | D11: =BS!D25/IS!D5*365 -> 71.715006 | E11: =BS!E25/IS!E5*365 -> 69.775262 | F11: 70 | G11: 69 | H11: 69 | I11: 68 | J11: 68
A12: DPO | C12: =BS!C56/IS!C19*365 -> 9.2018082 | D12: =BS!D56/IS!D19*365 -> 11.79757 | E12: =BS!E56/IS!E19*365 -> 11.783505 | F12: 12 | G12: 12 | H12: 11 | I12: 11 | J12: 11
A13: DIO | C13: 0 | D13: 0 | E13: 0 | F13: 0 | G13: 0 | H13: 0 | I13: 0 | J13: 0
A15: Capital Investment
A16: Capex % Revenue | C16: =CFS!C32/IS!C5 -> -0.01717548 | D16: =CFS!D32/IS!D5 -> -0.0143229 | E16: =CFS!E32/IS!E5 -> -0.013724768 | F16: -0.014 | G16: -0.014 | H16: -0.0145 | I16: -0.0147 | J16: -0.015
A18: Effective Tax Rate | C18: =(IS!C23+IS!C24)/IS!C21 -> 0.26467149 | D18: =(IS!D23+IS!D24)/IS!D21 -> 0.27064577 | E18: =(IS!E23+IS!E24)/IS!E21 -> 0.28871517 | F18: 0.28 | G18: 0.28 | H18: 0.28 | I18: 0.28 | J18: 0.28
A20: Depreciation % of Gross PP&E | C20: 0.085 | D20: 0.085 | E20: 0.085 | F20: 0.085 | G20: 0.085 | H20: 0.085 | I20: 0.085 | J20: 0.085
A22: Dividend Payout Ratio% | C22: 0.65 | D22: 0.65 | E22: 0.65 | F22: 0.65 | G22: 0.65 | H22: 0.65 | I22: 0.65 | J22: 0.65
A24: CWIP % of Capex | C24: 0.3 | D24: 0.3 | E24: 0.3 | F24: 0.3 | G24: 0.3 | H24: 0.3 | I24: 0.3 | J24: 0.3
A26: Provisions % of Revenue | C26: 0.01 | D26: 0.01 | E26: 0.01 | F26: 0.01 | G26: 0.01 | H26: 0.01 | I26: 0.01 | J26: 0.01

Sheet IS
A1: Infosys Limited
A2: Income Statement (₹ Crores)
A4: Line Item | C4: FY23 | D4: FY24 | E4: FY25 | F4: FY26E | G4: FY27E | H4: FY28E | I4: FY29E | J4: FY30E
A5: Revenue from operations | C5: 124014 | D5: 153670 | E5: 162990 | F5: =E5*(1+Assumptions!F4) -> 174399.3 | G5: =F5*(1+Assumptions!G4) -> 186607.25 | H5: =G5*(1+Assumptions!H4) -> 199296.54 | I5: =H5*(1+Assumptions!I4) -> 212250.82 | J5: =I5*(1+Assumptions!J4) -> 226047.12
A6: Other income, net | C6: 3859 | D6: 4711 | E6: 3600 | F6: =F5*0.025 -> 4359.9825 | G6: =G5*0.025 -> 4665.1813 | H6: =H5*0.025 -> 4982.4136 | I6: =I5*0.025 -> 5306.2705 | J6: =J5*0.025 -> 5651.1781
A7: Total income | C7: 127873 | D7: 158381 | E7: 166590 | F7: =F5+F6 -> 178759.28 | G7: =G5+G6 -> 191272.43 | H7: =H5+H6 -> 204278.96 | I7: =I5+I6 -> 217557.09 | J7: =J5+J6 -> 231698.3
A9: Expenses
A10: Employee benefit expenses | C10: 62764 | D10: 82620 | E10: 85950 | F10: =F5*(E10/E5) -> 91966.5 | G10: =G5*(F10/F5) -> 98404.155 | H10: =H5*(G10/G5) -> 105095.64 | I10: =I5*(H10/H5) -> 111926.85 | J10: =J5*(I10/I5) -> 119202.1
A11: Cost of technical sub contractors | C11: 19096 | D11: 12232 | E11: 12937 | F11: =F5*(E11/E5) -> 13842.59 | G11: =G5*(F11/F5) -> 14811.571 | H11: =H5*(G11/G5) -> 15818.758 | I11: =I5*(H11/H5) -> 16846.977 | J11: =J5*(I11/I5) -> 17942.031
A12: Travel expenses | C12: 1227 | D12: 1759 | E12: 1894 | F12: =F5*(E12/E5) -> 2026.58 | G12: =G5*(F12/F5) -> 2168.4406 | H12: =H5*(G12/G5) -> 2315.8946 | I12: =I5*(H12/H5) -> 2466.4277 | J12: =J5*(I12/I5) -> 2626.7455
A13: Cost of software packages and others | C13: 5214 | D13: 13515 | E13: 15911 | F13: =F5*(E13/E5) -> 17024.77 | G13: =G5*(F13/F5) -> 18216.504 | H13: =H5*(G13/G5) -> 19455.226 | I13: =I5*(H13/H5) -> 20719.816 | J13: =J5*(I13/I5) -> 22066.604
A14: Communication expenses | C14: 502 | D14: 677 | E14: 620 | F14: =F5*(E14/E5) -> 663.4 | G14: =G5*(F14/F5) -> 709.838 | H14: =H5*(G14/G5) -> 758.10698 | I14: =I5*(H14/H5) -> 807.38394 | J14: =J5*(I14/I5) -> 859.86389
A15: Consultancy and professional charges | C15: 1236 | D15: 1726 | E15: 1655 | F15: =F5*(E15/E5) -> 1770.85 | G15: =G5*(F15/F5) -> 1894.8095 | H15: =H5*(G15/G5) -> 2023.6565 | I15: =I5*(H15/H5) -> 2155.1942 | J15: =J5*(I15/I5) -> 2295.2818
A16: Depreciation and amortization expenses | C16: 2753 | D16: 4678 | E16: 4812 | F16: =F5*(E16/E5) -> 5148.84 | G16: =G5*(F16/F5) -> 5509.2588 | H16: =H5*(G16/G5) -> 5883.8884 | I16: =I5*(H16/H5) -> 6266.3411 | J16: =J5*(I16/I5) -> 6673.6533
A17: Finance cost | C17: 157 | D17: 470 | E17: 416 | F17: =F5*(E17/E5) -> 445.12 | G17: =G5*(F17/F5) -> 476.2784 | H17: =H5*(G17/G5) -> 508.66533 | I17: =I5*(H17/H5) -> 541.72858 | J17: =J5*(I17/I5) -> 576.94094
A18: Other expenses | C18: 3281 | D18: 4716 | E18: 4787 | F18: =F5*(E18/E5) -> 5122.09 | G18: =G5*(F18/F5) -> 5480.6363 | H18: =H5*(G18/G5) -> 5853.3196 | I18: =I5*(H18/H5) -> 6233.7853 | J18: =J5*(I18/I5) -> 6638.9814
A19: Total expenses | C19: 96230 | D19: 122393 | E19: 128982 | F19: =F10+F11+F12+F13+F14+F15+F16+F17+F18 -> 138010.74 | G19: =G10+G11+G12+G13+G14+G15+G16+G17+G18 -> 147671.49 | H19: =H10+H11+H12+H13+H14+H15+H16+H17+H18 -> 157713.15 | I19: =I10+I11+I12+I13+I14+I15+I16+I17+I18 -> 167964.51 | J19: =J10+J11+J12+J13+J14+J15+J16+J17+J18 -> 178882.2
A21: Profit before tax | C21: 31643 | D21: 35988 | E21: 37608 | F21: =F29-F17+F6 -> 44549.899 | G21: =G29-G17+G6 -> 47855 | H21: =H29-H17+H6 -> 51308.436 | I21: =I29-I17+I6 -> 54643.484 | J21: =J29-J17+J6 -> 58195.311
A23: Current tax | C23: 8167 | D23: 8390 | E23: 12130
A24: Deffered tax | C24: 208 | D24: 1350 | E24: -1272
A25: Total Tax expense | C25: =C23+C24 -> 8375 | D25: =D23+D24 -> 9740 | E25: =E23+E24 -> 10858 | F25: =F21*Assumptions!F18 -> 12473.972 | G25: =G21*Assumptions!G18 -> 13399.4 | H25: =H21*Assumptions!H18 -> 14366.362 | I25: =I21*Assumptions!I18 -> 15300.176 | J25: =J21*Assumptions!J18 -> 16294.687
A27: Profit for the year | C27: 23268 | D27: 26248 | E27: 26750 | F27: =F21-F25 -> 32075.928 | G27: =G21-G25 -> 34455.6 | H27: =H21-H25 -> 36942.074 | I27: =I21-I25 -> 39343.309 | J27: =J21-J25 -> 41900.624
A29: EBIT | C29: =C17+C21 -> 31800 | D29: =D17+D21 -> 36458 | E29: =E17+E21 -> 38024 | F29: =F5*Assumptions!F7 -> 40635.037 | G29: =G5*Assumptions!G7 -> 43666.097 | H29: =H5*Assumptions!H7 -> 46834.688 | I29: =I5*Assumptions!I7 -> 49878.943 | J29: =J5*Assumptions!J7 -> 53121.074
A31: Other comprehensive income
A32: Items that will not be reclassified subsequently to profit or loss
A33: Remeasurement of the net defined benefit liability/ asset, net | C33: -19 | D33: 0 | E33: -92
A34: Equity instruments through other comprehensive income, net | C34: -6 | D34: 0 | E34: 19
A35: Items that will be reclassified subsequently to profit or loss
A36: Fair value changes on derivatives designated as cash flow hedge, net | C36: -7 | D36: 0 | E36: -24
A37: Fair value changes on investments, net | C37: -236 | D37: 0 | E37: 199
A38: Total other comprehensive income/ (loss), net of tax | C38: -268 | D38: 0 | E38: 459
A39: Total comprehensive income for the year | C39: 23000 | D39: 0 | E39: 27209
A41: Profit attributable to:
A42: Owners of the company | C42: 0 | D42: 26233 | E42: 26713
A43: Non-controlling interests | C43: 0 | D43: 15 | E43: 37
C44: 0 | D44: 26248 | E44: 26750
A46: Total comprehensive income attributable to:
A47: Owners of the company | C47: 0 | D47: 26167 | E47: 27167
A48: Non-controlling interests | C48: 0 | D48: 42 | E48: 42
C49: 0 | D49: 27209 | E49: 27209
...

Sheet BS
A1: Infosys Limited
A2: Balance Sheet (₹ Crores)
A4: Line Item | C4: FY23 | D4: FY24 | E4: FY25 | F4: FY26E | G4: FY27E | H4: FY28E | I4: FY29E | J4: FY30E
A5: Assets
A7: Non current assets
A8: Property, plant and equipment | C8: ='PP&E Sch'!C14 -> 11656 | D8: ='PP&E Sch'!D14 -> 10813 | E8: ='PP&E Sch'!E14 -> 10070 | F8: ='PP&E Sch'!F14 -> 10163.125 | G8: ='PP&E Sch'!G14 -> 10219.627 | H8: ='PP&E Sch'!H14 -> 10331.364 | I8: ='PP&E Sch'!I14 -> 10427.755 | J8: ='PP&E Sch'!J14 -> 10529.559
A9: Right of use assets | C9: 3561 | D9: 6552 | E9: 6311 | F9: =E9 -> 6311 | G9: =F9 -> 6311 | H9: =G9 -> 6311 | I9: =H9 -> 6311 | J9: =I9 -> 6311
A10: Capital work in progress | C10: 275 | D10: 293 | E10: 814 | F10: ='PP&E Sch'!F7*Assumptions!F24 -> 732.47706 | G10: ='PP&E Sch'!G7*Assumptions!G24 -> 783.75045 | H10: ='PP&E Sch'!H7*Assumptions!H24 -> 866.93997 | I10: ='PP&E Sch'!I7*Assumptions!I24 -> 936.02611 | J10: ='PP&E Sch'!J7*Assumptions!J24 -> 1017.2121
A11: Goodwill | C11: 211 | D11: 7303 | E11: 10106 | F11: =E11 -> 10106 | G11: =F11 -> 10106 | H11: =G11 -> 10106 | I11: =H11 -> 10106 | J11: =I11 -> 10106
A12: Other intangible assets | C12: 3 | D12: 1397 | E12: 2766 | F12: =E12 -> 2766 | G12: =F12 -> 2766 | H12: =G12 -> 2766 | I12: =H12 -> 2766 | J12: =I12 -> 2766
A13: Financial assets
A14: Investments | C14: 23686 | D14: 11708 | E14: 11059 | F14: =E14 -> 11059 | G14: =F14 -> 11059 | H14: =G14 -> 11059 | I14: =H14 -> 11059 | J14: =I14 -> 11059
A15: Loans | C15: 39 | D15: 34 | E15: 16 | F15: =E15 -> 16 | G15: =F15 -> 16 | H15: =G15 -> 16 | I15: =H15 -> 16 | J15: =I15 -> 16
A16: Other financial assets | C16: 1341 | D16: 3105 | E16: 3511 | F16: =E16 -> 3511 | G16: =F16 -> 3511 | H16: =G16 -> 3511 | I16: =H16 -> 3511 | J16: =I16 -> 3511
A17: Deferred tax assets (net) | C17: 779 | D17: 454 | E17: 1108 | F17: =E17 -> 1108 | G17: =F17 -> 1108 | H17: =G17 -> 1108 | I17: =H17 -> 1108 | J17: =I17 -> 1108
A18: Income tax assets (net) | C18: 5916 | D18: 3045 | E18: 1622 | F18: =E18 -> 1622 | G18: =F18 -> 1622 | H18: =G18 -> 1622 | I18: =H18 -> 1622 | J18: =I18 -> 1622
A19: Other non-current assets | C19: 1788 | D19: 2121 | E19: 2713 | F19: =E19 -> 2713 | G19: =F19 -> 2713 | H19: =G19 -> 2713 | I19: =H19 -> 2713 | J19: =I19 -> 2713
A20: Total non-current assets | C20: 49255 | D20: 48382 | E20: 51804 | F20: =SUM(F8:F19) -> 50107.602 | G20: =F20 -> 50107.602 | H20: =G20 -> 50107.602 | I20: =H20 -> 50107.602 | J20: =I20 -> 50107.602
A22: Current assets
A23: Financial assets
A24: Investments | C24: 4476 | D24: 12915 | E24: 12482 | F24: =E24 -> 12482 | G24: =F24 -> 12482 | H24: =G24 -> 12482 | I24: =H24 -> 12482 | J24: =I24 -> 12482
A25: Trade receivables | C25: 20773 | D25: 30193 | E25: 31158 | F25: ='WC Sch'!F5 -> 33446.441 | G25: ='WC Sch'!G5 -> 35276.439 | H25: ='WC Sch'!H5 -> 37675.237 | I25: ='WC Sch'!I5 -> 39542.618 | J25: ='WC Sch'!J5 -> 42112.889
A26: Cash and cash equivalents | C26: 6534 | D26: 14786 | E26: 24455
A27: Loans | C27: 291 | D27: 248 | E27: 249 | F27: =E27 -> 249 | G27: =F27 -> 249 | H27: =G27 -> 249 | I27: =H27 -> 249 | J27: =I27 -> 249
A28: Other financial assets | C28: 9088 | D28: 12085 | E28: 13840 | F28: =E28 -> 13840 | G28: =F28 -> 13840 | H28: =G28 -> 13840 | I28: =H28 -> 13840 | J28: =I28 -> 13840
A29: Income tax assets (net) | C29: =-C30 -> -10920 | D29: 6397 | E29: 2975 | F29: =E29 -> 2975 | G29: =F29 -> 2975 | H29: =G29 -> 2975 | I29: =H29 -> 2975 | J29: =I29 -> 2975
A30: Other current assets | C30: 10920 | D30: 12808 | E30: 11940 | F30: =E30 -> 11940 | G30: =F30 -> 11940 | H30: =G30 -> 11940 | I30: =H30 -> 11940 | J30: =I30 -> 11940
A31: Total current assets | C31: 52082 | D31: 89432 | E31: 97099 | F31: =SUM(F24:F30) -> 74932.441 | G31: =F31 -> 74932.441 | H31: =G31 -> 74932.441 | I31: =H31 -> 74932.441 | J31: =I31 -> 74932.441
A33: Total assets | C33: 101337 | D33: 137814 | E33: 148903
A35: Equity
A37: Equity share capital | C37: 2074 | D37: 2071 | E37: 2073 | F37: =E37 -> 2073 | G37: =F37 -> 2073 | H37: =G37 -> 2073 | I37: =H37 -> 2073 | J37: =I37 -> 2073
A38: Other equity | C38: 65671 | D38: 86045 | E38: 93745 | F38: =E38+IS!F27-(IS!F27*Assumptions!F22) -> 104971.57 | G38: =F38+IS!G27-(IS!G27*Assumptions!G21) -> 139427.17 | H38: =G38+IS!H27-(IS!H27*Assumptions!H21) -> 176369.25 | I38: =H38+IS!I27-(IS!I27*Assumptions!I21) -> 215712.56 | J38: =I38+IS!J27-(IS!J27*Assumptions!J21) -> 257613.18
A39: Total equity attributable to equity holders of the company | E39: =E37+E38 -> 95818 | F39: =F37+F38 -> 107044.57 | G39: =G37+G38 -> 141500.17 | H39: =H37+H38 -> 178442.25 | I39: =I37+I38 -> 217785.56 | J39: =J37+J38 -> 259686.18
A40: Non-controlling interests | E40: 385 | F40: 385 | G40: 385 | H40: 385 | I40: 385 | J40: 385
A41: Total equity | C41: 67745 | D41: 88461 | E41: 96203 | F41: =SUM(F39:F40) -> 107429.57 | G41: =SUM(G39:G40) -> 141885.17 | H41: =SUM(H39:H40) -> 178827.25 | I41: =SUM(I39:I40) -> 218170.56 | J41: =SUM(J39:J40) -> 260071.18
A43: Liabilities
A45: Non-current liabilities
A46: Financial liabilities
A47: Lease liabilities | C47: 3553 | D47: 6400 | E47: 5772 | F47: 5772 | G47: 5772 | H47: 5772 | I47: 5772 | J47: 5772
A48: Other financial libilities | C48: 1317 | D48: 2130 | E48: 2141 | F48: 2141 | G48: 2141 | H48: 2141 | I48: 2141 | J48: 2141
...

Sheet CFS
A1: Infosys Limited
A2: Cash Flow Statement (₹ Crores)
A4: Line Item | C4: FY23 | D4: FY24 | E4: FY25
A5: Cash fow from operating activities
A7: Profit for the year | C7: 23268 | D7: 26248 | E7: 26750
A8: Adjustments to reconcile net profit to net cash provided by operating activities
A9: Depreciation and amortization | C9: 2753 | D9: 4678 | E9: 4812
A10: Income tax expense | C10: 8375 | D10: 9740 | E10: 10858
A11: Impairment loss recognized/(reversed) under expected credit loss model | C11: 183 | D11: 121 | E11: 48
A12: Finance cost | C12: 157 | D12: 470 | E12: 416
A13: Interest and dividend income | C13: -3028 | D13: -2067 | E13: -2570
A14: Stock compensation expense | C14: 460 | D14: 652 | E14: 802
A15: Provision for post sale client support | C15: 121 | D15: 75 | E15: -110
A16: Exchange differences on translation of assets and liabilities, net | C16: -116 | D16: 76 | E16: 79
A17: Interest receivable on income tax refund | C17: 0 | D17: -1934 | E17: -327
A18: Other adjustments | C18: 34 | D18: 1464 | E18: 833
A20: Changes in assets and liabilities
A21: Trade receivables and unbilled revenue | C21: -5065 | D21: -2667 | E21: -1769
A22: Loans, other financial assets and other assets | C22: -2171 | D22: -1172 | E22: -1024
A23: Trade payables | C23: -243 | D23: 91 | E23: 176
A24: Other financial liabilities, other liabilities and provisions | C24: 2248 | D24: -1334 | E24: 2322
A26: Cash generated from operations | C26: 26976 | D26: 34441 | E26: 41296
A27: Income taxes paid | C27: -7807 | D27: -9231 | E27: -5602
A28: Net cash generated by operating activities | C28: 19169 | D28: 25210 | E28: 35694
A30: Cash flow from investing activities
A32: Expenditure on property, plant and equipment | C32: -2130 | D32: -2201 | E32: -2237
A33: Deposits placed with corporation | C33: -634 | D33: -847 | E33: -1225
A34: Redemption of deposits placed with corporation | C34: 482 | D34: 710 | E34: 776
A35: Interest and dividend received | C35: 1299 | D35: 1768 | E35: 2040
A36: Dividend received from subsidiary | C36: 1463 | D36: 0 | E36: 0
A37: Loan given to subsidiaries | C37: -427 | D37: 0 | E37: 0
A38: Loan repaid by subsidiaries | C38: 393 | D38: 0 | E38: 0
A39: Investment in subsidiaries | C39: -1530 | D39: 0 | E39: 0
A40: Receipt / (payment) towards business transfer for entities under common control | C40: 19 | D40: 0 | E40: 0
A41: Receipt / (payment) from entities under liquidation | C41: 0 | D41: 0 | E41: 0
A42: Escrow and other deposits pertaining to buyback | C42: -483 | D42: 0 | E42: 0
A43: Payment towards acquisition of business, net of cash acquired | C43: 0 | D43: 0 | E43: -3155
... A46: Other receipts | C46: 61 | D46: 128 | E46: 10
A47: Payments to acquire investments
A48: Liquid mutual fund units | C48: -62952 | D48: -66191 | E48: -73048
...

Sheet Check
A2: Check | C2: FY23 | D2: FY24 | E2: FY25
C3: =BS!C45-(BS!C70+BS!C80) -> 0 | D3: =BS!D45-(BS!D70+BS!D80) -> 0 | E3: =BS!E45-(BS!E70+BS!E80) -> 0

Sheet PP&E Sch
A1: Infosys Limited
A2: PP&E Schedule (₹ Crores)
A4: Line Item | C4: FY23 | D4: FY24 | E4: FY25 | F4: FY26E | G4: FY27E | H4: FY28E | I4: FY29E | J4: FY30E
A5: Gross PP&E
A6: Opening gross PP&E | F6: =E8 -> 27629 | G6: =F8 -> 30070.59 | H6: =G8 -> 32683.092 | I6: =H8 -> 35572.892 | J6: =I8 -> 38692.979
A7: Capex | F7: =-(Assumptions!F16)*IS!F5 -> 2441.5902 | G7: =-(Assumptions!G16)*IS!G5 -> 2612.5015 | H7: =-(Assumptions!H16)*IS!H5 -> 2889.7999 | I7: =-(Assumptions!I16)*IS!I5 -> 3120.087 | J7: =-(Assumptions!J16)*IS!J5 -> 3390.7068
A8: Closing gross PP&E | C8: 26709 | D8: 27240 | E8: 27629 | F8: =(F7)+F6 -> 30070.59 | G8: =(G7)+G6 -> 32683.092 | H8: =(H7)+H6 -> 35572.892 | I8: =(I7)+I6 -> 38692.979 | J8: =(J7)+J6 -> 42083.685
A10: Opening Accumulated depreciation | F10: =E12 -> 17559 | G10: =F12 -> 19907.465 | H10: =G12 -> 22463.465 | I10: =H12 -> 25241.528 | J10: =I12 -> 28265.224
A11: Depreciation expense | F11: =F6*Assumptions!F20 -> 2348.465 | G11: =G6*Assumptions!G20 -> 2556.0002 | H11: =H6*Assumptions!H20 -> 2778.0628 | I11: =I6*Assumptions!I20 -> 3023.6958 | J11: =J6*Assumptions!J20 -> 3288.9032
A12: Closing accumulated depreciation | C12: 15053 | D12: 16427 | E12: 17559 | F12: =F10+F11 -> 19907.465 | G12: =G10+G11 -> 22463.465 | H12: =H10+H11 -> 25241.528 | I12: =I10+I11 -> 28265.224 | J12: =J10+J11 -> 31554.127
A14: Net PP&E | C14: =C8-C12 -> 11656 | D14: =D8-D12 -> 10813 | E14: =E8-E12 -> 10070 | F14: =F8-F12 -> 10163.125 | G14: =G8-G12 -> 10219.627 | H14: =H8-H12 -> 10331.364 | I14: =I8-I12 -> 10427.755 | J14: =J8-J12 -> 10529.559

Sheet WC Sch
A1: Infosys Limited
A2: PP&E Schedule (₹ Crores)
A4: Line Item | C4: FY23 | D4: FY24 | E4: FY25 | F4: FY26E | G4: FY27E | H4: FY28E | I4: FY29E | J4: FY30E
A5: Receivables | C5: =Assumptions!C11/365*IS!C5 -> 20773 | D5: =Assumptions!D11/365*IS!D5 -> 30193 | E5: =Assumptions!E11/365*IS!E5 -> 31158 | F5: =Assumptions!F11/365*IS!F5 -> 33446.441 | G5: =Assumptions!G11/365*IS!G5 -> 35276.439 | H5: =Assumptions!H11/365*IS!H5 -> 37675.237 | I5: =Assumptions!I11/365*IS!I5 -> 39542.618 | J5: =Assumptions!J11/365*IS!J5 -> 42112.889
A6: Payables | C6: =Assumptions!C12/365*IS!C19 -> 2426 | D6: =Assumptions!D12/365*IS!D19 -> 3956 | E6: =Assumptions!E12/365*IS!E19 -> 4164 | F6: =Assumptions!F12/365*IS!F19 -> 4537.3394 | G6: =Assumptions!G12/365*IS!G19 -> 4854.9532 | H6: =Assumptions!H12/365*IS!H19 -> 4752.9991 | I6: =Assumptions!I12/365*IS!I19 -> 5061.9441 | J6: =Assumptions!J12/365*IS!J19 -> 5390.9704
A7: Inventory | C7: =Assumptions!C13/365 -> 0 | D7: =Assumptions!D13/365 -> 0 | E7: =Assumptions!E13/365 -> 0 | F7: =Assumptions!F13/365 -> 0 | G7: =Assumptions!G13/365 -> 0 | H7: =Assumptions!H13/365 -> 0 | I7: =Assumptions!I13/365 -> 0 | J7: =Assumptions!J13/365 -> 0

Sheet Sheet1

Sheet WACC

Sheet DCF

Sheet Sensitivity
